Workbook
Name Agency_Abrv: [1]Codes!$H$5:$H$40
Name Agency_Names: [1]Codes!$I$5:$M$40
Name Agency_Selected: '[1]First Sheet'!$A$10
Name BegPeriod: [1]Codes!$B$25:$B$28
Name Code_Sheet_Title: [1]Codes!$A$48
Name Current_Period: '[1]First Sheet'!$A$7
Name CurrentBeg: '[1]First Sheet'!$B$7
Name CurrentEnd: '[1]First Sheet'!$C$7
Name DueDates: #REF!
Name DueDates: #REF!
Name DueDates: #REF!
Name DueDates: #REF!
Name EndPeriod: [1]Codes!$C$25:$C$28
Name Eval_Status: [1]Codes!$A$10:$A$13
Name Exact_Match: [1]Codes!$A$57
Name First_Sheet_Title: [1]Codes!$A$33
Name Frequency: [2]DropDownMenus!$I$1:$I$7
Name General_Title: [1]Codes!$A$36
Name holidays: OFFSET([3]Holidays!$A$10,1,0,COUNTA([3]Holidays!$A$11:$A$4996),1)
Name Input_Sheet_Title: [1]Codes!$A$42
Name Instruction_Sheet_Title: [1]Codes!$A$45
Name LevelDetail: [2]DropDownMenus!$C$1:$C$4
Name LSUSRoles: OFFSET([4]RolesLSUS!$A$1,0,0,COUNTA([4]RolesLSUS!$A:$A),1)
Name Method: [2]DropDownMenus!$J$1:$J$5
Name MPF: [2]DropDownMenus!$S$2:$S$5
Name No_Changes: [1]Codes!$A$55
Name No_Data_Entry: [1]Codes!$A$51
Name Policy_Units: [1]Codes!$A$16:$A$22
Name Quarters: [1]Codes!$A$25:$A$28
Name refCategory: '[5]Reference Values'!$B$20:$B$26
Name refIgnore: #REF!
Name refImpact: '[5]Reference Values'!$B$39:$B$43
Name refProbability: '[5]Reference Values'!$B$32:$B$36
Name refRiskRankingTable: #REF!
Name refRRImpact: '[5]Reference Values'!$B$39:$C$43
Name refRRProbability: '[5]Reference Values'!$B$32:$C$36
Name Reporting_Level_Title: '[1]First Sheet'!$B$10
Name RoleList: OFFSET([4]Sheet2!$A$1,0,0,COUNTA([4]Sheet2!$A:$A),1)
Name RolesLSE: OFFSET([4]RolesLSE!$A$1,0,0,COUNTA([4]RolesLSE!$A:$A),1)
Name Row_height: [1]Codes!$A$53
Name Selected_Unit_Title: '[1]First Sheet'!$B$13
Name SF: [2]DropDownMenus!$Q$2:$Q$13
Name Summary_Sheet_Title: [1]Codes!$A$39
Name Timing: [2]DropDownMenus!$O$1:$O$3
Name Unit_Selected: '[1]First Sheet'!$A$13
Name Unit_Titles: [1]Codes!$B$16:$E$22
Name valuevx: 42.314159
Name WIF: [2]DropDownMenus!$U$2:$U$16
Name Yes_No: [1]Codes!$A$6:$A$7

Sheet Intake Form
A1: IAS Project Intake
A3: Submission Date | C3: 44608 | AY3: Approved
A4: Project Title | C4: CloudMed DRG Validation & Underpayment Implementation | L4: Strata # | AY4: Rejected
L5: IAS SN # | AY5: Hold
A6: Project Description | C6: Accurate DRG selection & payer payment according to contract are critical to maximized revenue. Implementing CloudMed's DRG Validation & Underpayment Services is expected to increase revenue by $1M-$7M annually. 2022 AHWFB Budget expects $500k for both. If not implemented by May 2022, this revenue will be delayed & cause negative variance to budget. | AY6: Other
I7: Business Sponsor | L7: Underpays, D. Lauten; DRG Val, G. DiCrocco
I8: IAS Project Sponsor | L8: Robert Oliver
J10: Discovery Meeting Date | M10: 44596 | AY10: Yes
A11: Requested | C11: Deliver necessary technical enablers based on CloudMed's implementation plan, and support Operations to ensure smooth operationalization of tech enablers. | J11: Proposed Start Date | M11: 44593 | AY11: No
A12: IAS Services | J12: Proposed Go Live Date | M12: 44682
J13: Proposed End Date | M13: 44805
A14: Sustaining Functionality
C15: No | F15: New Product / Service | G15: Yes | J15: Project is Mandated | K15: No | M15: Impact | N15: ='Impact Scoring'!D19 -> Medium
F16: Enhancement to Existing P/S | G16: No | J16: (Regulatory or Compliance) | M16: Risk | N16: =M31+M33+M35 -> 16
A18: Governing Committee | D18: =IF(K15="Yes",Hidden!A4,IF(C15="Yes",Hidden!A2,IF('Intake Form'!G15="Yes",Hidden!A3,IF('Intake Form'!G16="Yes",Hidden!A4,"N/A")))) -> CEO Council (CEOC) | M18: T-Shirt | N18: =IF('Resource Estimates'!T33<41,"XS",IF('Resource Estimates'!T33<81,"S",IF('Resource Estimates'!T33<201,"M",IF('Resource Estimates'!T33<501,"L",IF('Resource Estimates'!T33>500,"XL","N/A"))))) -> L
A20: Project Outcomes | C20: Implement CloudMed services by May 2022 and begin realizing additional revenue by July 2022, for a total of $500k for each service in 2022.
A23: Project Justification | C23: 2022 AHWFB Budget expects $500k for both. If not implemented by May 2022, this revenue will be delayed & cause negative variance to budget.
A30: Risk Analysis - Risk of not doing | G30: Category | I30: Probability | K30: Impact | M30: Risk Score | Z30: Probability | AA30: Impact
A31: Negative Budget Variance of $1M | G31: Business | I31: Likely | K31: Major | M31: =IFERROR(Z31*AA31, 0) -> 16 | Z31: =IF(I31="Almost Certain", 5, IF(I31="Likely", 4, IF(I31="Possible", 3, IF(I31="Unlikely", 2, IF(I31="Rare",1, "N/A"))))) -> 4 | AA31: =IF(K31="Severe", 5, IF(K31="Major", 4, IF(K31="Moderate", 3, IF(K31="Minor", 2, IF(K31="Insignificant",1, "N/A"))))) -> 4
M33: =IFERROR(Z33*AA33, 0) -> 0 | Z33: =IF(I33="Almost Certain", 5, IF(I33="Likely", 4, IF(I33="Possible", 3, IF(I33="Unlikely", 2, IF(I33="Rare",1, "N/A"))))) -> N/A | AA33: =IF(K33="Severe", 5, IF(K33="Major", 4, IF(K33="Moderate", 3, IF(K33="Minor", 2, IF(K33="Insignificant",1, "N/A"))))) -> N/A
M35: =IFERROR(Z35*AA35, 0) -> 0 | Z35: =IF(I35="Almost Certain", 5, IF(I35="Likely", 4, IF(I35="Possible", 3, IF(I35="Unlikely", 2, IF(I35="Rare",1, "N/A"))))) -> N/A | AA35: =IF(K35="Severe", 5, IF(K35="Major", 4, IF(K35="Moderate", 3, IF(K35="Minor", 2, IF(K35="Insignificant",1, "N/A"))))) -> N/A
A39: Project Funding | D39: Grant | F39: No | I39: Grant Name
A40: Is funding needed? | D40: Amount
A41: No
A42: Fiscal Year Carry Over | D42: Business OpEx | F42: 0 | H42: IAS OpEx | J42: 0 | M42: Other Expenses
A43: No | D43: Business CapEx | F43: 0 | H43: IAS CapEx | J43: 0 | M43: 0
A46: Support Funding | C46: Fiscal Year 1 (Project) | E46: Fiscal Year 2 | G46: Fiscal Year 3 | I46: Fiscal Year 4 | K46: Fiscal Year 5 | M46: Total
A47: IAS OpEx
B48: Maint/ License | C48: 0 | E48: 0 | G48: 0 | I48: 0 | K48: 0 | M48: =SUM(C48:L48) -> 0
B49: Services | C49: 0 | E49: 0 | G49: 0 | I49: 0 | K49: 0 | M49: =SUM(C49:L49) -> 0
B50: Hardware | C50: 0 | E50: 0 | G50: 0 | I50: 0 | K50: 0 | M50: =SUM(C50:L50) -> 0
C51: =SUM(C48:D50) -> 0 | E51: =SUM(E48:F50) -> 0 | G51: =SUM(G48:H50) -> 0 | I51: =SUM(I48:J50) -> 0 | K51: =SUM(K48:L50) -> 0 | M51: =SUM(M48:N50) -> 0
A53: IAS CapEx | C53: 0 | E53: 0 | G53: 0 | I53: 0 | K53: 0 | M53: =SUM(C53:L53) -> 0
B54: Combined Yearly | C54: =C53+C51 -> 0 | E54: =E53+E51 -> 0 | G54: =G53+G51 -> 0 | I54: =I53+I51 -> 0 | K54: =K53+K51 -> 0 | M54: =M53+M51 -> 0
A58: IAS Opinion | C58: IAS concerns or issues with project or work effort
C62: PHI Implications | G62: PCI Implications | I62: FISMA Implications | M62: IAS Annual
M63: Support Hours
C64: Hosted Services | G64: IAS Standards Compliant | J64: IPT Involved
A66: IAS Reviews Completed | D66: Data | G66: Technical | J66: Security | M66: Applications
A67: IAS Reviews Satisfactory | D67: Data | G67: Technical | J67: Security | M67: Applications
...

Sheet Submission Data1
B1: Project Submission Form
B2: Project: | C2: ='Intake Form'!C4:H4 -> CloudMed DRG Validation & Underpayment Implementation | E2: Project #:
B3: Project Manager: | E3: Sponsor: | K3: Customer Based Data
B4: Project Artifacts: | E4: Last Update:
B6: Background (Statement of Problem) | K6: The "problem" AFFECTS…... (Users / stakeholders]…Who specifically is impacted?
B7: Business need | K7: the IMPACT of which is…. Statement of issues, costs, or other impacts]… Lacking a solution what are the impacts and outcomes suffered as a result of the business problem? (In other words, what’s the business driver; why may the company be compelled to solve the problem?)
B8: Objectives (What is to be achieved) | K8: A SUCCESSFUL SOLUTION would be …...(Important benefits that would successfully solve the problem). What characteristics and qualities does an acceptable and/or compelling product / solution include? What would a (generic) product / solution do or have that addresses or resolves key issues and needs
B10: Scope | C10: In Scope | E10: Out of Scope | K10: Solution Value
K12: Describe Value in terms of increased clinical, patient, or business value inside and outside WFBH.
B14: Deliverables (Deliverables and Associated Key Milestones) | C14: Deliverable | F14: Deliverable / Key Milestone Target Dates
F15: Kick-Off
K17: Identification of key metrics for measuring success of implementation and/or usage.
F18: Design/Build
F21: Go-Live
K22: Value Options
K24: Is this request to replace existing software? If yes, why is your current software inadequate? Describe: Feature / function short comings, or express operational impacts / failures resulting from the existing software.
B26: Vendor | F26: Vendor Solution (Product/ Component) Name(s)
B28: Vendor Contact
K29: Is there any interim value that can be provided prior to the product / service delivery? Express any additional value that could be achieved with existing owned business capabilities prior to purchase or delivery. Answer the question, if the purchase is delayed or not approved how will you gain value until purchase of the product / service? Identification of key metrics for measuring interim success are helpful
B30: General Contract Terms
B35: Signatures
B36: Business Sponsor | K36: What will be the impact(s) of the application / product to clinical operations?
C37: Signature
K38: Positive Impacts to clinical operations: How does the application / solution the operations environment in which it will operate? | R38: Negative Impacts / Risks to clinical operations: How does the application / solution negatively affect the operations environment in which it will operate? Are there any risks with the product in an operations environment? | Y38: Success Criteria
C39: Printed Name
C41: Date
B43: ITS Sponsor
C45: Signature
C47: Printed Name
C49: Date

Sheet Submission Data - 1
B1: Project Submission Form
B2: Project: | C2: ='Intake Form'!C4 -> CloudMed DRG Validation & Underpayment Implementation | E2: Project #: | F2: ='Intake Form'!M5 -> 0
B3: Project Manager: | E3: Business Sponsor: | F3: ='Intake Form'!L7 -> Underpays, D. Lauten; DRG Val, G. DiCrocco
B5: Background (Statement of Problem) | C5: ='Intake Form'!C6 -> Accurate DRG selection & payer payment according to contract are critical to maximized revenue. Implementing CloudMed's DRG Validation & Underpayment Services is expected to increase revenue by $1M-$7M annually. 2022 AHWFB Budget expects $500k for both. If not implemented by May 2022, this revenue will be delayed & cause negative variance to budget.
B6: Business need | C6: ='Intake Form'!C23 -> 2022 AHWFB Budget expects $500k for both. If not implemented by May 2022, this revenue will be delayed & cause negative variance to budget.
B7: Objectives (What is to be achieved) | C7: ='Intake Form'!C20 -> Implement CloudMed services by May 2022 and begin realizing additional revenue by July 2022, for a total of $500k for each service in 2022.
B9: Scope | C9: In Scope | F9: Out of Scope
C10: DRG Validation - Data Spec, scheduled for recurring submission via sFTP drop
C11: Underpayments - Data Spec (same as above, + Epic Application build
C12: i.e. WQ's, Claim Edits, Billing Indicators, etc
C13: May change after Ops designs future state once IT approval and kick-off can occur
B15: Deliverables (Deliverables and Associated Key Milestones) | C15: Deliverable | F15: Deliverable / Key Milestone Target Dates
C17: Kick-Off | F17: 44620
C18: Payer Contracts provided and loaded | F18: 3/7-4/4
C19: ITS Build | F19: 3/7-4/15
C20: Ops Design | F20: 3/7-4/15
C21: Testing | F21: 4/16-4/30
C22: Training | F22: 4/16-4/30
C23: Go-live | F23: 44682
C24: Revenue Realization Begins | F24: 44743
C25: Project Closure - operationalization | F25: 44805
C27: This is current draft of timeline, given project is still in Initiation Phase
C28: Hard dates are Go-live and revenue realization dates
B36: Vendor | C36: ='Intake Form'!C69 -> CloudMed | F36: Vendor Solution (Product/ Component) Name(s)
B38: Vendor Contact | C38: Justin Licht <Justin.Licht@cloudmed.com>
B40: General Contract Terms | C40: Exisiting Contract | F40: New Contract
B41: Start Date | C41: Check with Atrium IAS
B42: End Date
B43: Terms of Contract
B46: Signatures
B47: Business Sponsor
C48: Signature
C50: Printed Name | D50: ='Intake Form'!L7 -> Underpays, D. Lauten; DRG Val, G. DiCrocco
C52: Date
B54: IAS Sponsor
C56: Signature
C58: Printed Name | D58: ='Intake Form'!L8 -> Robert Oliver
C60: Date

Sheet Submission Data - 2
A3: Customer Based Data
A4: The "problem" AFFECTS…... (Users / stakeholders]…Who specifically is impacted? | E4: Every employee in AHWFB
A5: the IMPACT of which is…. Statement of issues, costs, or other impacts]… Lacking a solution what are the impacts and outcomes suffered as a result of the business problem? (In other words, what’s the business driver; why may the company be compelled to solve the problem?) | E5: Accurate DRG selection & payer payment according to contract are critical to maximized revenue. Implementing CloudMed's DRG Validation & Underpayment Services is expected to increase revenue by $1M-$7M annually. 2022 AHWFB Budget expects $500k for both. If not implemented by May 2022, this revenue will be delayed & cause negative variance to budget. This project critical to increasing AHWFB's margin. Without this project, margin target may not be hit. If 1% is not achieved, then each employee does not get additional 1% employer base retirement contribution which is contingent on > 1% margin
A6: A SUCCESSFUL SOLUTION would be …... (Important benefits that would successfully solve the problem). What characteristics and qualities does an acceptable and/or compelling product / solution include? What would a (generic) product / solution do or have that addresses or resolves key issues and needs | E6: Implemented by 5/1/2022 and realizing additional revenue by 7/1/2022
A8: Solution Value
A10: Describe Value in terms of increased clinical, patient, or business value inside and outside WFBH. | E10: Accurate DRG selection & payer payment according to contract are critical to maximized revenue. Implementing CloudMed's DRG Validation & Underpayment Services is expected to increase revenue by $1M-$7M annually. 2022 AHWFB Budget expects $500k for both. If not implemented by May 2022, this revenue will be delayed & cause negative variance to budget.
A15: Identification of key metrics for measuring success of implementation and/or usage. | E15: Underpayment Recoveries as % NPSR DRG Improvement as % IP Payments Baselines on both have been determined
A20: Value Options
A22: Is this request to replace existing software? If yes, why is your current software inadequate? Describe: Feature / function short comings, or express operational impacts / failures resulting from the existing software. | E22: Operating as secondary behind current vendors (STAT Rev for Underpayments and Enjoin for DRG Validation)
A27: Is there any interim value that can be provided prior to the product / service delivery? Express any additional value that could be achieved with existing owned business capabilities prior to purchase or delivery. Answer the question, if the purchase is delayed or not approved how will you gain value until purchase of the product / service? Identification of key metrics for measuring interim success are helpful | E27: We have already engaged in recurring performance meetings with existing vendors through PFS VMO. This has driven up Enjoin performance by $10.6M since January 2020. however, improvement is leveling out, indicating need for other effort.
A34: What will be the impact(s) of the application / product to clinical operations?
A36: Positive Impacts to clinical operations: How does the application / solution the operations environment in which it will operate? | E36: Negative Impacts / Risks to clinical operations: How does the application / solution negatively affect the operations environment in which it will operate? Are there any risks with the product in an operations environment? | H36: Success Criteria
H38: Critical that one Project Manager oversees all aspects of implementation (this is PFS PM, with insight into IT)
A40: More revenue means more investment in clinical operations | E40: None | H40: Critical that ITS identify resources to complete build and engaged in kick-off.
H42: IT PM would help with IT work coordination

Sheet Impact Scoring
A1: Impact Scoring
B3: Low Impact (1) | C3: Medium Impact (3) | D3: High Impact (5) | E3: Rating | F3: Weight | G3: Score
A4: Departments | B4: One | C4: One to Two | D4: At least three. Cross-functional team required | E4: 5 | F4: 3 | G4: =E4*F4 -> 15
A5: Complexity | B5: Simple, requirements should be understood through an email | C5: Requirements should be understood by IAS through one meeting involving one or two customers | D5: Requirements need to be gathered through multiple meetings with a variety of stakeholders throughout campus | E5: 5 | F5: 3 | G5: =F5*E5 -> 15
A6: Resolution Time | B6: < 80 managed hours | C6: 80-480 managed hours | D6: >480 managed hours | E6: 3 | F6: 3 | G6: =F6*E6 -> 9
A7: Deadline | B7: Flexible. Low impact | C7: Somewhat flexible. Some impact | D7: Fixed. Significant impact | E7: 5 | F7: 3 | G7: =F7*E7 -> 15
A8: Cost | B8: Uses existing resources. No additional budget | C8: Requires budget up to $49,999 | D8: Budget at least $50,000 | E8: 1 | F8: 3 | G8: =F8*E8 -> 3
A9: Resource Scarcity* | B9: No competing requests. Little to no impact on scarce resources | C9: Resource limited. Increased analysis and consideration of alternatives | D9: Resource intensive. Significant impact | E9: 3 | F9: 5 | G9: =F9*E9 -> 15
A10: Risk / Visibility | B10: Low Risk. Project can revert to prior state easily. Little to no negative impact on stakeholders | C10: Moderate risk. Project can revert back with some downtime and loss of use. Failure may create moderate inconvenience and visibility | D10: High risk. High visibility. Significant impact on work processes. | E10: 5 | F10: 5 | G10: =F10*E10 -> 25
A11: Funding | B11: The project is completely funded. | D11: The project is not completely funded. | E11: 1 | F11: 5 | G11: =F11*E11 -> 5
A12: Patient Outcomes | B12: Does not affect patient outcomes | C12: Indirectly affects patient care, outcome. | D12: Improves patient care, outcome, and safety at all sites. | E12: 1 | F12: 5 | G12: =F12*E12 -> 5
A13: Compliance/Contractual | B13: No contractual obligations or compliance impact | C13: Minor contractual obligation or compliance issue | D13: Major contractual obligation or compliance issue | E13: 3 | F13: 5 | G13: =F13*E13 -> 15
A14: Ongoing Costs | B14: Negligible impact on staff to maintain with minimal budget impact | C14: Some impact on staffing less than 5 FTE to support with budget impact less than $100K | D14: Significant impact on staffing more than 5 FTE to support with budget impact over $100K | E14: 1 | F14: 5 | G14: =F14*E14 -> 5
A16: *Resource scarcity can include key project participants with impacted schedules or new technology requiring skills and experience not currently available to the project team.
A18: Impact Score Range | C18: Impact Score | D18: =SUM(G4:G14) -> 127
A19: Low Impact | B19: 45-100 | C19: Impact | D19: =IF(D18=0, "N/A", IF(D18<101, "Low", IF(D18<175, "Medium", IF(D18>175, "High", "N/A")))) -> Medium
A20: Medium Impact | B20: 100-175
A21: High Impact | B21: 175-225

Sheet Business Outcome BR Pathway
B1: Technology Request Benefits Realization Template
B2: Request
D3: ='Intake Form'!C4 -> CloudMed DRG Validation & Underpayment Implementation
B5: Business Outcome Benefits Realization Pathway | D5: Business Strategy | F5: Goals & Objectives | H5: Key Business Objectives | J5: Key Performance Indicators | L5: Operational Indicators | O5: Measure Defined | P5: Unit of Measure | Q5: Baseline Measure | R5: Target Measure | S5: Timeframe to Achieve | T5: Responsible Party for Measure
D7: What is to be accomplished? | F7: What are the Goals and objectives that will be realized with the strategy? | H7: What are the most important actionable steps to met he goals and objectives? | J7: What measures of success are tied to the drivers? | L7: Define operational Metrics | O7: Underpayment Recovery | P7: Underpayment as % NPSR | Q7: 0.00053 | R7: 0.0007 | S7: 44743 | T7: C. Brown
L8: Define operational Metrics
L9: Define operational Metrics
H10: Key Business Objectives | J10: Key Performance Indicators | L10: Financial Indicators | O10: Measure Defined | P10: Unit of Measure | Q10: Baseline Measure | R10: Target Measure | S10: Timeframe to Achieve | T10: Responsible Party for Measure
H12: What are the most important actionable steps to met he goals and objectives? | J12: What measures of success are tied to the drivers? | L12: Define Financial Metric | O12: DRG Improvement | P12: DRG Improvement as % IP Payments | Q12: 0.0061 | R12: 0.01 | S12: 44743 | T12: C. Brown
L13: Define Financial Metric
L14: Define Financial Metric
H15: Key Business Objectives | J15: Key Performance Indicators | L15: Strategic Indicators | O15: Measure Defined | P15: Unit of Measure | Q15: Baseline Measure | R15: Target Measure | S15: Timeframe to Achieve | T15: Responsible Party for Measure
H17: What are the most important actionable steps to met he goals and objectives? | J17: What measures of success are tied to the drivers? | L17: Define Strategic KPI | O17: Underpayment Recovery | P17: Underpayment as % NPSR | Q17: 0.00053 | R17: 0.0007 | S17: 44743 | T17: C. Brown
L18: Define Strategic KPI
L19: Define Strategic KPI

Sheet Business Change BR Pathway 
B2: Technology Request Benefits Realization Template
B3: Request
D4: ='Intake Form'!C4 -> CloudMed DRG Validation & Underpayment Implementation
B6: Business Change Benefits Realization Pathway | L6: Growth of Business | O6: Measure Defined | P6: Unit of Measure | Q6: Baseline Measure | R6: Target Measure | S6: Timeframe to Achieve | T6: Responsible Party for Measure
D7: Business Problem | F7: Change | H7: Benefit | J7: Benefit Indicators
D8: What is the current business problem? | F8: What has to change within the business? | H8: What is the benefit of change? | J8: What measures are indicators of change? | L8: Define Growth Metrics
L9: Define Growth Metrics
L10: Define Growth Metrics
L11: Transformation of Business | O11: Measure Defined | P11: Unit of Measure | Q11: Baseline Measure | R11: Target Measure | S11: Timeframe to Achieve | T11: Responsible Party for Measure
H12: Benefit | J12: Benefit Indicators
H13: What is the benefit of change? | J13: What measures are indicators of change? | L13: Define Transformation Metrics
L14: Define Transformation Metrics
L15: Define Transformation Metrics
L16: Running of Business | O16: Measure Defined | P16: Unit of Measure | Q16: Baseline Measure | R16: Target Measure | S16: Timeframe to Achieve | T16: Responsible Party for Measure
H17: Benefit | J17: Benefit Indicators
H18: What is the benefit of change? | J18: What measures are indicators of change? | L18: Define Business / Operational Metrics
L19: Define Business / Operational Metrics
L20: Define Business / Operational Metrics

Sheet Process Outcome BR Pathway
B2: Technology Request Benefits Realization Template
B3: Request
D4: ='Intake Form'!C4 -> CloudMed DRG Validation & Underpayment Implementation
B6: Process Outcome Benefits Realization Pathway
D7: Business Impact | F7: Processes | H7: Process Input | J7: Process Activities | L7: Process Outcomes
D8: What business capabilities are impacted? | F8: What is a key process associated with capabilities? | H8: What are the resource contribution changes? | J8: What work is conducted to achieve objectives & Activities directly linked to outcomes? | L8: What are the product or service delivered?
O10: Measure Defined | P10: Unit of Measure | Q10: Baseline Measure | R10: Target Measure | S10: Timeframe to Achieve | T10: Responsible Party for Measure
F12: Resource Productivity
F13: Resource Volumes
H14: Process Effectiveness
H15: Process Reliability
H16: Process Cycle time
H17: Process Cost
J18: Process Compliance
J19: Process Quality
J20: Product / Service Cost
L21: Process Outcomes
F22: Processes | H22: Process Input | J22: Process Activities
F23: What is a key process associated with capabilities? | H23: What are the resource contribution changes? | J23: What work is conducted to achieve objectives & Activities directly linked to outcomes? | L23: What are the product or service delivered?
O25: Measure Defined | P25: Unit of Measure | Q25: Baseline Measure | R25: Target Measure | S25: Timeframe to Achieve | T25: Responsible Party for Measure
F27: Resource Productivity
F28: Resource Volumes
H29: Process Effectiveness
H30: Process Reliability
H31: Process Cycle time
H32: Process Cost
J33: Process Compliance
J34: Process Quality
J35: Product / Service Cost
L36: Process Outcomes
F37: Processes | H37: Process Input | J37: Process Activities
F38: What is a key process associated with capabilities? | H38: What are the resource contribution changes? | J38: What work is conducted to achieve objectives & Activities directly linked to outcomes? | L38: What are the product or service delivered?
O40: Measure Defined | P40: Unit of Measure | Q40: Baseline Measure | R40: Target Measure | S40: Timeframe to Achieve | T40: Responsible Party for Measure
F42: Resource Productivity
F43: Resource Volumes
H44: Process Effectiveness
H45: Process Reliability
H46: Process Cycle time
H47: Process Cost
J48: Process Compliance
...

Sheet Resource Estimates
A1: IAS to fill out - IAS Resource Estimates
A2: Resource Estimates by Assignment Group - Hours by Month
A3: Assignment Group | B3: 44562 | C3: =EDATE(B3,1) -> 44593 | D3: =EDATE(C3,1) -> 44621 | E3: =EDATE(D3,1) -> 44652 | F3: =EDATE(E3,1) -> 44682 | G3: =EDATE(F3,1) -> 44713 | H3: =EDATE(G3,1) -> 44743 | I3: =EDATE(H3,1) -> 44774 | J3: =EDATE(I3,1) -> 44805 | ... S3: =EDATE(R3,1) -> 45078 | T3: Total Hours
A4: Data Management - Analytics | C4: 20 | D4: 40 | E4: 40 | F4: 10 | G4: 5 | H4: 5 | I4: 5 | J4: 5 | T4: =SUM(B4:S4) -> 130
A5: InfoSec - EPIC Access and Security | D5: 5 | E5: 5 | F5: 5 | T5: =SUM(B5:S5) -> 15
A6: Hospital Based Billing | C6: 0 | D6: 80 | E6: 80 | F6: 30 | G6: 5 | H6: 5 | I6: 5 | J6: 5 | T6: =SUM(B6:S6) -> 210
A7: ITS-PMO | C7: 0 | D7: 5 | E7: 5 | F7: 5 | T7: =SUM(B7:S7) -> 15
A8: Data Management - Data Integration | D8: 10 | E8: 10 | F8: 5 | T8: =SUM(B8:S8) -> 25
T9: =SUM(B9:S9) -> 0
T10: =SUM(B10:S10) -> 0
T11: =SUM(B11:S11) -> 0
T12: =SUM(B12:S12) -> 0
T13: =SUM(B13:S13) -> 0
T14: =SUM(B14:S14) -> 0
T15: =SUM(B15:S15) -> 0
T16: =SUM(B16:S16) -> 0
T17: =SUM(B17:S17) -> 0
T18: =SUM(B18:S18) -> 0
T19: =SUM(B19:S19) -> 0
T20: =SUM(B20:S20) -> 0
... T32: =SUM(B32:S32) -> 0
A33: Total Hours | B33: =SUM(B4:B32) -> 0 | C33: =SUM(C4:C32) -> 20 | D33: =SUM(D4:D32) -> 140 | E33: =SUM(E4:E32) -> 140 | F33: =SUM(F4:F32) -> 55 | G33: =SUM(G4:G32) -> 10 | H33: =SUM(H4:H32) -> 10 | I33: =SUM(I4:I32) -> 10 | ... T33: =SUM(T4:T32) -> 395

Sheet Change Request
A1: PROJECT CHANGE REQUEST FORM
A5: Change Request Number | D5: Project # | G5: Date:
A7: Project Name:
A9: Project Manager:
A11: Business Sponsor:
A14: Change Details
A16: Change Requested By:
A18: Email Address:
A20: Contact Number:
A22: Location:
A24: Reason For Change:
A30: Change Impact Analysis
A32: Action
A33: (How/What/Where/When?)
... A37: How will this Change affect the following?
A38: Delivery Date: | C38: Cost: | E38: Schedule: | G38: Scope:
A41: Authorization
A43: Expenditure Approved | E43: Approved
A44: Sponsor Sign Off: | E44: ITS Sign Off:
A47: Change Close-Out
A49: Follow up Comments:
A53: Has appropriate and effective action been implemented?
A55: Business Sponsor Name:
A57: Project Manager Name:

Sheet Hidden
A1: Committees | E1: Assignment Groups
A2: IT Steering Committee (ITSC) | E2: 3M
A3: CEO Council (CEOC) | E3: Academic Applications (Education)
A4: Chief Medical Officers (CMO) | E4: Academic Applications (Research)
E5: Ambulatory Systems
E6: ARB
E7: Beaker
E8: Cadence
E9: ClinDoc
E10: Clinical Device Integration
E11: Clinical Research
E12: Collaboration Services
E13: Configuration Management
E14: Core Client Services
E15: Cornerstone AMB
E16: Data Management - Analytics
... E78: Wireless
